Workbook

Sheet About
A1: BECbIC - BAU Employee Compensation by ISIC Code
A3: State: South Dakota (SD) Base year: 2019 Pipeline: EPS IO Pipeline — stateior-based
A4: Deflator: 2019 USD -> 2012 USD = 1.12266 (BEA chained GDP price index; 2012 = 100.000, 2019 = 112.266)
A6: =========================================================
A7: Methodology
A8: =========================================================
A9: Employee compensation by ISIC is the V001 row of stateior's
A10: ValueAdded component per industry, aggregated to 42 ISIC using the
A11: canonical BEA-to-ISIC crosswalk.
A13: Deflated from nominal 2019 USD to 2012 USD.
A15: In-workbook derivation
A16: ----------------------
... A139: 11. BECbIC - final compensation vector (matches BECbIC.csv)

Sheet Keys
A1: category | B1: key | C1: value | D1: description
A2: deflator | B2: deflator_nominal_to_2012 | C2: 1.12266 | D2: Divide nominal 2019 USD by this to get 2012 USD. BEA chained GDP price index; 2012 = 100.000, 2019 = 112.266
A3: year | B3: base_year | C3: 2019 | D3: stateior base year; nominal-USD vintage of the source tabs
A4: numeric | B4: epsilon_div_floor | C4: 1e-09 | D4: Denominator floor for ratio outputs (DCS, ESoP): x/MAX(den, epsilon) avoids div-by-zero; mirrors pmax(den, 1e-9) in the R pipeline
A5: numeric | B5: fogp_denom_floor_usd | C5: 1 | D5: FoGP-entity denominator floor: total purchases per category floored at $1 (mirrors pmax(total, 1)); near-zero totals give near-zero fractions

Sheet 1_Source_V001_Compensation
A1: BEA_Summary_code | B1: comp_USD_2019nominal
A2: 111CA | B2: 7.1318884e+08
A3: 113FF | B3: 1.0801428e+08
A4: 211 | B4: 1355864.2
A5: 212 | B5: 29594697
A6: 213 | B6: 2564714.5
A7: 22 | B7: 2.4362308e+08
A8: 23 | B8: 1.4252582e+09
A9: 321 | B9: 1.3508066e+08
A10: 327 | B10: 80491249
A11: 331 | B11: 32503656
A12: 332 | B12: 1.8185436e+08
A13: 333 | B13: 4.7894435e+08
... A72: GSLE | B72: 1.8182749e+08

Sheet 1b_Source_ValueAdded_full
A1: VA_row (V001-V003) | B1: 111CA | C1: 113FF | D1: 211 | E1: 212 | F1: 213 | G1: 22 | H1: 23 | I1: 321 | J1: 327 | K1: 331 | L1: 332 | M1: 333 | N1: 334 | O1: 335 | P1: 3361MV | Q1: 3364OT | R1: 337 | S1: 339 | T1: 311FT | U1: 313TT | V1: 315AL | W1: 322 | X1: 323 | Y1: 324 | Z1: 325 | AA1: 326 | AB1: 42 | AC1: 441 | AD1: 445 | AE1: 452 | AF1: 4A0 | AG1: 481 | AH1: 482 | AI1: 483 | AJ1: 484 | AK1: 485 | AL1: 486 | AM1: 487OS | AN1: 493 | AO1: 511 | AP1: 512 | AQ1: 513 | AR1: 514 | AS1: 521CI | AT1: 523 | AU1: 524 | AV1: 525 | AW1: HS | AX1: ORE | AY1: 532RL | AZ1: 5411 | BA1: 5415 | BB1: 5412OP | BC1: 55 | BD1: 561 | BE1: 562 | BF1: 61 | BG1: 621 | BH1: 622 | BI1: 623 | BJ1: 624 | BK1: 711AS | BL1: 713 | BM1: 721 | BN1: 722 | BO1: 81 | BP1: GFGD | BQ1: GFGN | BR1: GFE | BS1: GSLG | BT1: GSLE
A2: V001 | B2: 7.1318884e+08 | C2: 1.0801428e+08 | D2: 1355864.2 | E2: 29594697 | F2: 2564714.5 | G2: 2.4362308e+08 | H2: 1.4252582e+09 | I2: 1.3508066e+08 | J2: 80491249 | K2: 32503656 | L2: 1.8185436e+08 | M2: 4.7894435e+08 | N2: 97274873 | O2: 55812542 | P2: 1.5246878e+08 | Q2: 20087829 | R2: 98983485 | S2: 4.3283568e+08 | T2: 3.1542877e+08 | U2: 26713994 | V2: 1986693 | W2: 31150112 | X2: 78353775 | Y2: 511638.94 | Z2: 67630313 | AA2: 50983602 | AB2: 1.5673689e+09 | AC2: 5.3366781e+08 | AD2: 3.1139372e+08 | AE2: 3.3375233e+08 | AF2: 8.4452942e+08 | AG2: 33476092 | AH2: 84939906 | AI2: 349210.65 | AJ2: 4.0482062e+08 | AK2: 32011882 | AL2: 7110997.5 | AM2: 1.6616904e+08 | AN2: 48288388 | AO2: 57958669 | AP2: 14877046 | AQ2: 2.7045893e+08 | AR2: 34191337 | AS2: 3.6022666e+09 | AT2: 2.0785334e+08 | AU2: 6.5189854e+08 | AV2: 2590997.2 | AW2: 53695710 | AX2: 1.1122679e+08 | AY2: 29551631 | AZ2: 1.3699346e+08 | BA2: 2.9460293e+08 | BB2: 7.5764881e+08 | BC2: 6.5246995e+08 | BD2: 5.7139466e+08 | BE2: 49425718 | BF2: 3.0372596e+08 | BG2: 1.667821e+09 | BH2: 2.0591946e+09 | BI2: 4.9348854e+08 | BJ2: 2.6991476e+08 | BK2: 56552036 | BL2: 1.2648142e+08 | BM2: 3.204059e+08 | BN2: 6.8859473e+08 | BO2: 8.3169737e+08 | BP2: 4.5987501e+08 | BQ2: 4.3987938e+08 | BR2: 1.2599037e+08 | BS2: 3.7960063e+09 | BT2: 1.8182749e+08
A3: V002 | B3: -2.8246533e+08 | C3: 7597083.1 | D3: 1588182.5 | E3: 9094195.6 | F3: 165947.14 | G3: 1.8442309e+08 | H3: 27002972 | I3: 4704274.4 | J3: 4339928.9 | K3: 2645058 | L3: 6793331.6 | M3: 18779735 | N3: 5509666 | O3: 1528530.8 | P3: 7727099.6 | Q3: 715963.65 | R3: 2024401 | S3: 15367213 | T3: 75339127 | U3: 1359875.3 | V3: 81609.315 | W3: 1890968.8 | X3: 2450118 | Y3: 104520.25 | Z3: 11822177 | AA3: 2457235.2 | AB3: 7.8882841e+08 | AC3: 2.2207683e+08 | AD3: 84437690 | AE3: 1.5044751e+08 | AF3: 3.4110542e+08 | AG3: 15201459 | AH3: 361776.3 | AI3: 54442.941 | AJ3: 18247842 | AK3: 2322946.1 | AL3: 3199367.8 | AM3: 4482820.3 | AN3: 759701.51 | AO3: 3223562.9 | AP3: 2386095.2 | AQ3: 1.051733e+08 | AR3: 1777908.7 | AS3: 2.5977878e+08 | AT3: 4932572.8 | AU3: 74928207 | AV3: 689230.77 | AW3: 5.9181378e+08 | AX3: 32720103 | AY3: 17049826 | AZ3: 17116079 | BA3: 7598376.3 | BB3: 18870953 | BC3: 18297235 | BD3: 14984475 | BE3: 5981465.5 | BF3: 14625792 | BG3: 29033779 | BH3: 77138455 | BI3: 24064302 | BJ3: 4931428.7 | BK3: 7336893.7 | BL3: 35727831 | BM3: 1.1728053e+08 | BN3: 1.2763575e+08 | BO3: 64938369 | BP3: 0 | BQ3: 0 | BR3: -13295425 | BS3: 0 | BT3: -33420542
A4: V003 | B4: 2.6243516e+09 | C4: 47488633 | D4: 4655909.3 | E4: 44009550 | F4: 2069338.3 | G4: 4.905566e+08 | H4: 8.1734122e+08 | I4: 62115064 | J4: 74771354 | K4: 29251286 | L4: 81554014 | M4: 2.5877592e+08 | N4: 57915461 | O4: 30360388 | P4: 1.4690412e+08 | Q4: 17196208 | R4: 33292114 | S4: 2.3629711e+08 | T4: 3.168321e+08 | U4: 7926130.2 | V4: 431957.58 | W4: 27158920 | X4: 41296107 | Y4: 2883816.4 | Z4: 1.5044751e+08 | AA4: 31959163 | AB4: 1.2830027e+09 | AC4: 3.1340128e+08 | AD4: 1.1233062e+08 | AE4: 67945151 | AF4: 6.2061156e+08 | AG4: 25922449 | AH4: 85198318 | AI4: 296346.41 | AJ4: 3.0043153e+08 | AK4: 21465172 | AL4: 21989635 | AM4: 62748139 | AN4: 5651910.9 | AO4: 72817768 | AP4: 16336480 | AQ4: 8.2077015e+08 | AR4: 37730754 | AS4: 5.3422671e+09 | AT4: 9814886.6 | AU4: 6.5157326e+08 | AV4: -1680227.9 | AW4: 3.8422322e+09 | AX4: 4.8212051e+08 | AY4: 1.2889782e+08 | AZ4: 1.2248951e+08 | BA4: 58698696 | BB4: 3.2398024e+08 | BC4: 69632818 | BD4: 1.8092087e+08 | BE4: 29592817 | BF4: 66146821 | BG4: 4.5594518e+08 | BH4: 3.9226699e+08 | BI4: 33847160 | BJ4: 26253811 | BK4: 55511070 | BL4: 45490744 | BM4: 2.4681357e+08 | BN4: 1.9896745e+08 | BO4: 2.8166426e+08 | BP4: 2.8520982e+08 | BQ4: 2.7843453e+08 | BR4: 22498207 | BS4: 6.0501084e+08 | BT4: 89906809
A5: V001 | B5: 0 | C5: 0 | D5: 0 | E5: 0 | F5: 0 | G5: 0 | H5: 0 | I5: 0 | J5: 0 | K5: 0 | L5: 0 | M5: 0 | N5: 0 | O5: 0 | P5: 0 | Q5: 0 | R5: 0 | S5: 0 | T5: 0 | U5: 0 | V5: 0 | W5: 0 | X5: 0 | Y5: 0 | Z5: 0 | AA5: 0 | AB5: 0 | AC5: 0 | AD5: 0 | AE5: 0 | AF5: 0 | AG5: 0 | AH5: 0 | AI5: 0 | AJ5: 0 | AK5: 0 | AL5: 0 | AM5: 0 | AN5: 0 | AO5: 0 | AP5: 0 | AQ5: 0 | AR5: 0 | AS5: 0 | AT5: 0 | AU5: 0 | AV5: 0 | AW5: 0 | AX5: 0 | AY5: 0 | AZ5: 0 | BA5: 0 | BB5: 0 | BC5: 0 | BD5: 0 | BE5: 0 | BF5: 0 | BG5: 0 | BH5: 0 | BI5: 0 | BJ5: 0 | BK5: 0 | BL5: 0 | BM5: 0 | BN5: 0 | BO5: 0 | BP5: 0 | BQ5: 0 | BR5: 0 | BS5: 0 | BT5: 0
A6: V002 | B6: 0 | C6: 0 | D6: 0 | E6: 0 | F6: 0 | G6: 0 | H6: 0 | I6: 0 | J6: 0 | K6: 0 | L6: 0 | M6: 0 | N6: 0 | O6: 0 | P6: 0 | Q6: 0 | R6: 0 | S6: 0 | T6: 0 | U6: 0 | V6: 0 | W6: 0 | X6: 0 | Y6: 0 | Z6: 0 | AA6: 0 | AB6: 0 | AC6: 0 | AD6: 0 | AE6: 0 | AF6: 0 | AG6: 0 | AH6: 0 | AI6: 0 | AJ6: 0 | AK6: 0 | AL6: 0 | AM6: 0 | AN6: 0 | AO6: 0 | AP6: 0 | AQ6: 0 | AR6: 0 | AS6: 0 | AT6: 0 | AU6: 0 | AV6: 0 | AW6: 0 | AX6: 0 | AY6: 0 | AZ6: 0 | BA6: 0 | BB6: 0 | BC6: 0 | BD6: 0 | BE6: 0 | BF6: 0 | BG6: 0 | BH6: 0 | BI6: 0 | BJ6: 0 | BK6: 0 | BL6: 0 | BM6: 0 | BN6: 0 | BO6: 0 | BP6: 0 | BQ6: 0 | BR6: 0 | BS6: 0 | BT6: 0
A7: V003 | B7: 0 | C7: 0 | D7: 0 | E7: 0 | F7: 0 | G7: 0 | H7: 0 | I7: 0 | J7: 0 | K7: 0 | L7: 0 | M7: 0 | N7: 0 | O7: 0 | P7: 0 | Q7: 0 | R7: 0 | S7: 0 | T7: 0 | U7: 0 | V7: 0 | W7: 0 | X7: 0 | Y7: 0 | Z7: 0 | AA7: 0 | AB7: 0 | AC7: 0 | AD7: 0 | AE7: 0 | AF7: 0 | AG7: 0 | AH7: 0 | AI7: 0 | AJ7: 0 | AK7: 0 | AL7: 0 | AM7: 0 | AN7: 0 | AO7: 0 | AP7: 0 | AQ7: 0 | AR7: 0 | AS7: 0 | AT7: 0 | AU7: 0 | AV7: 0 | AW7: 0 | AX7: 0 | AY7: 0 | AZ7: 0 | BA7: 0 | BB7: 0 | BC7: 0 | BD7: 0 | BE7: 0 | BF7: 0 | BG7: 0 | BH7: 0 | BI7: 0 | BJ7: 0 | BK7: 0 | BL7: 0 | BM7: 0 | BN7: 0 | BO7: 0 | BP7: 0 | BQ7: 0 | BR7: 0 | BS7: 0 | BT7: 0

Sheet Src_Stateior_SoI_Make
A1: State-of-Interest Make matrix (V) at BEA Summary resolution, from EPA
A2: stateior's two-region MRIO build for this state and base year. Rows =
A3: industries, columns = commodities. Values are in nominal 2019 USD as
A4: emitted by stateior. This is the raw input aggregated to 42 ISIC for
A5: the final output in this workbook.
A8: industry | B8: 111CA | C8: 113FF | D8: 211 | E8: 212 | F8: 213 | G8: 22 | H8: 23 | I8: 321 | J8: 327 | K8: 331 | L8: 332 | M8: 333 | N8: 334 | O8: 335 | P8: 3361MV | Q8: 3364OT | R8: 337 | S8: 339 | T8: 311FT | U8: 313TT | V8: 315AL | W8: 322 | X8: 323 | Y8: 324 | Z8: 325 | AA8: 326 | AB8: 42 | AC8: 441 | AD8: 445 | AE8: 452 | AF8: 4A0 | AG8: 481 | AH8: 482 | AI8: 483 | AJ8: 484 | AK8: 485 | AL8: 486 | AM8: 487OS | AN8: 493 | AO8: 511 | AP8: 512 | AQ8: 513 | AR8: 514 | AS8: 521CI | AT8: 523 | AU8: 524 | AV8: 525 | AW8: HS | AX8: ORE | AY8: 532RL | AZ8: 5411 | BA8: 5415 | BB8: 5412OP | BC8: 55 | BD8: 561 | BE8: 562 | BF8: 61 | BG8: 621 | BH8: 622 | BI8: 623 | BJ8: 624 | BK8: 711AS | BL8: 713 | BM8: 721 | BN8: 722 | BO8: 81 | BP8: GFGD | BQ8: GFGN | BR8: GFE | BS8: GSLG | BT8: GSLE | BU8: Used | BV8: Other
A9: 111CA | B9: 9.4824229e+09 | C9: 1.3655045e+08 | D9: 0 | E9: 0 | F9: 0 | G9: 0 | H9: 0 | I9: 112463.69 | J9: 0 | K9: 0 | L9: 0 | M9: 0 | N9: 0 | O9: 0 | P9: 0 | Q9: 0 | R9: 0 | S9: 0 | T9: 0 | U9: 0 | V9: 0 | W9: 0 | X9: 0 | Y9: 0 | Z9: 0 | AA9: 0 | AB9: 0 | AC9: 0 | AD9: 0 | AE9: 0 | AF9: 0 | AG9: 0 | AH9: 0 | AI9: 0 | AJ9: 0 | AK9: 0 | AL9: 0 | AM9: 0 | AN9: 0 | AO9: 0 | AP9: 0 | AQ9: 0 | AR9: 0 | AS9: 0 | AT9: 0 | AU9: 0 | AV9: 0 | AW9: 0 | AX9: 0 | AY9: 0 | AZ9: 0 | BA9: 0 | BB9: 0 | BC9: 0 | BD9: 0 | BE9: 0 | BF9: 0 | BG9: 0 | BH9: 0 | BI9: 0 | BJ9: 0 | BK9: 0 | BL9: 48612867 | BM9: 0 | BN9: 0 | BO9: 0 | BP9: 0 | BQ9: 0 | BR9: 0 | BS9: 0 | BT9: 0 | BU9: 0 | BV9: 0
A10: 113FF | B10: 26801.864 | C10: 1.9932601e+08 | D10: 0 | E10: 0 | F10: 0 | G10: 0 | H10: 646188.87 | I10: 0 | J10: 0 | K10: 0 | L10: 0 | M10: 0 | N10: 0 | O10: 0 | P10: 0 | Q10: 0 | R10: 0 | S10: 0 | T10: 0 | U10: 0 | V10: 0 | W10: 0 | X10: 0 | Y10: 0 | Z10: 0 | AA10: 0 | AB10: 0 | AC10: 0 | AD10: 0 | AE10: 0 | AF10: 0 | AG10: 0 | AH10: 0 | AI10: 0 | AJ10: 0 | AK10: 0 | AL10: 0 | AM10: 0 | AN10: 0 | AO10: 0 | AP10: 0 | AQ10: 0 | AR10: 0 | AS10: 0 | AT10: 0 | AU10: 0 | AV10: 0 | AW10: 0 | AX10: 0 | AY10: 0 | AZ10: 0 | BA10: 0 | BB10: 0 | BC10: 0 | BD10: 0 | BE10: 0 | BF10: 0 | BG10: 0 | BH10: 0 | BI10: 0 | BJ10: 0 | BK10: 0 | BL10: 0 | BM10: 0 | BN10: 0 | BO10: 0 | BP10: 0 | BQ10: 0 | BR10: 0 | BS10: 0 | BT10: 0 | BU10: 0 | BV10: 0
A11: 211 | B11: 0 | C11: 0 | D11: 2822053.8 | E11: 344.99939 | F11: 79934.253 | G11: 0 | H11: 8127.176 | I11: 0 | J11: 0 | K11: 0 | L11: 0 | M11: 399.58853 | N11: 0 | O11: 0 | P11: 0 | Q11: 0 | R11: 0 | S11: 0 | T11: 0 | U11: 0 | V11: 0 | W11: 0 | X11: 0 | Y11: 10971492 | Z11: 3746.131 | AA11: 0 | AB11: 7597.037 | AC11: 0 | AD11: 0 | AE11: 0 | AF11: 0 | AG11: 0 | AH11: 0 | AI11: 0 | AJ11: 0 | AK11: 0 | AL11: 0 | AM11: 0 | AN11: 0 | AO11: 0 | AP11: 0 | AQ11: 0 | AR11: 0 | AS11: 0 | AT11: 0 | AU11: 0 | AV11: 0 | AW11: 0 | AX11: 0 | AY11: 0 | AZ11: 0 | BA11: 787.91293 | BB11: 4367.5667 | BC11: 0 | BD11: 0 | BE11: 0 | BF11: 0 | BG11: 0 | BH11: 0 | BI11: 0 | BJ11: 0 | BK11: 0 | BL11: 0 | BM11: 0 | BN11: 0 | BO11: 0 | BP11: 0 | BQ11: 0 | BR11: 0 | BS11: 0 | BT11: 0 | BU11: 0 | BV11: 0
A12: 212 | B12: 0 | C12: 0 | D12: 0 | E12: 1.3399453e+08 | F12: 6908723.2 | G12: 0 | H12: 12818543 | I12: 0 | J12: 249492.28 | K12: 0 | L12: 0 | M12: 0 | N12: 0 | O12: 0 | P12: 0 | Q12: 0 | R12: 0 | S12: 0 | T12: 0 | U12: 0 | V12: 0 | W12: 0 | X12: 0 | Y12: 4860748.1 | Z12: 5836387.2 | AA12: 0 | AB12: 524102.65 | AC12: 0 | AD12: 0 | AE12: 0 | AF12: 0 | AG12: 0 | AH12: 0 | AI12: 0 | AJ12: 0 | AK12: 0 | AL12: 0 | AM12: 0 | AN12: 0 | AO12: 0 | AP12: 0 | AQ12: 0 | AR12: 0 | AS12: 0 | AT12: 0 | AU12: 0 | AV12: 0 | AW12: 0 | AX12: 0 | AY12: 0 | AZ12: 0 | BA12: 3215.3537 | BB12: 106106.67 | BC12: 0 | BD12: 0 | BE12: 0 | BF12: 0 | BG12: 0 | BH12: 0 | BI12: 0 | BJ12: 0 | BK12: 0 | BL12: 0 | BM12: 0 | BN12: 0 | BO12: 0 | BP12: 0 | BQ12: 0 | BR12: 0 | BS12: 0 | BT12: 0 | BU12: 0 | BV12: 0
A13: 213 | B13: 0 | C13: 0 | D13: 24057.747 | E13: 0 | F13: 8609206.3 | G13: 0 | H13: 573023.59 | I13: 0 | J13: 0 | K13: 0 | L13: 45408.475 | M13: 0 | N13: 0 | O13: 0 | P13: 0 | Q13: 0 | R13: 0 | S13: 0 | T13: 0 | U13: 0 | V13: 0 | W13: 0 | X13: 0 | Y13: 243793.15 | Z13: 0 | AA13: 0 | AB13: 31819.405 | AC13: 0 | AD13: 0 | AE13: 0 | AF13: 0 | AG13: 0 | AH13: 0 | AI13: 0 | AJ13: 0 | AK13: 0 | AL13: 0 | AM13: 0 | AN13: 0 | AO13: 0 | AP13: 0 | AQ13: 0 | AR13: 0 | AS13: 0 | AT13: 0 | AU13: 0 | AV13: 0 | AW13: 0 | AX13: 0 | AY13: 0 | AZ13: 0 | BA13: 3497.3915 | BB13: 22424.451 | BC13: 0 | BD13: 0 | BE13: 0 | BF13: 0 | BG13: 0 | BH13: 0 | BI13: 0 | BJ13: 0 | BK13: 0 | BL13: 0 | BM13: 0 | BN13: 0 | BO13: 0 | BP13: 0 | BQ13: 0 | BR13: 0 | BS13: 0 | BT13: 0 | BU13: 0 | BV13: 0
A14: 22 | B14: 0 | C14: 0 | D14: 239685.13 | E14: 0 | F14: 0 | G14: 1.3985174e+09 | H14: 7582194.7 | I14: 0 | J14: 0 | K14: 0 | L14: 0 | M14: 0 | N14: 0 | O14: 0 | P14: 0 | Q14: 0 | R14: 0 | S14: 0 | T14: 0 | U14: 0 | V14: 0 | W14: 0 | X14: 0 | Y14: 0 | Z14: 0 | AA14: 0 | AB14: 4152615.9 | AC14: 0 | AD14: 0 | AE14: 0 | AF14: 2487691.2 | AG14: 0 | AH14: 0 | AI14: 0 | AJ14: 0 | AK14: 0 | AL14: 8039287.2 | AM14: 0 | AN14: 0 | AO14: 0 | AP14: 0 | AQ14: 0 | AR14: 0 | AS14: 0 | AT14: 0 | AU14: 0 | AV14: 0 | AW14: 0 | AX14: 0 | AY14: 0 | AZ14: 0 | BA14: 1144116.3 | BB14: 340741.67 | BC14: 0 | BD14: 0 | BE14: 5348.7436 | BF14: 0 | BG14: 0 | BH14: 0 | BI14: 0 | BJ14: 0 | BK14: 0 | BL14: 0 | BM14: 0 | BN14: 0 | BO14: 0 | BP14: 0 | BQ14: 0 | BR14: 0 | BS14: 0 | BT14: 12385821 | BU14: 0 | BV14: 0
A15: 23 | B15: 0 | C15: 0 | D15: 0 | E15: 0 | F15: 0 | G15: 0 | H15: 4.1244669e+09 | I15: 0 | J15: 0 | K15: 0 | L15: 0 | M15: 0 | N15: 0 | O15: 0 | P15: 0 | Q15: 0 | R15: 0 | S15: 0 | T15: 0 | U15: 0 | V15: 0 | W15: 0 | X15: 0 | Y15: 0 | Z15: 0 | AA15: 0 | AB15: 0 | AC15: 0 | AD15: 0 | AE15: 0 | AF15: 0 | AG15: 0 | AH15: 0 | AI15: 0 | AJ15: 0 | AK15: 0 | AL15: 0 | AM15: 0 | AN15: 0 | AO15: 0 | AP15: 0 | AQ15: 0 | AR15: 0 | AS15: 0 | AT15: 0 | AU15: 0 | AV15: 0 | AW15: 0 | AX15: 0 | AY15: 0 | AZ15: 0 | BA15: 859770.04 | BB15: 54777.593 | BC15: 0 | BD15: 0 | BE15: 0 | BF15: 0 | BG15: 0 | BH15: 0 | BI15: 0 | BJ15: 0 | BK15: 0 | BL15: 0 | BM15: 0 | BN15: 0 | BO15: 0 | BP15: 0 | BQ15: 0 | BR15: 0 | BS15: 0 | BT15: 0 | BU15: 0 | BV15: 0
A16: 321 | B16: 0 | C16: 0 | D16: 0 | E16: 0 | F16: 0 | G16: 0 | H16: 6148887.1 | I16: 5.8553025e+08 | J16: 802051.83 | K16: 0 | L16: 4188572.9 | M16: 0 | N16: 0 | O16: 0 | P16: 0 | Q16: 0 | R16: 2714387.2 | S16: 0 | T16: 0 | U16: 0 | V16: 0 | W16: 73333.627 | X16: 0 | Y16: 0 | Z16: 469588.77 | AA16: 1883575 | AB16: 10760552 | AC16: 0 | AD16: 0 | AE16: 0 | AF16: 0 | AG16: 0 | AH16: 0 | AI16: 0 | AJ16: 0 | AK16: 0 | AL16: 0 | AM16: 0 | AN16: 0 | AO16: 0 | AP16: 0 | AQ16: 0 | AR16: 0 | AS16: 0 | AT16: 0 | AU16: 0 | AV16: 0 | AW16: 0 | AX16: 0 | AY16: 0 | AZ16: 0 | BA16: 191067.11 | BB16: 920596.1 | BC16: 0 | BD16: 0 | BE16: 0 | BF16: 0 | BG16: 0 | BH16: 0 | BI16: 0 | BJ16: 0 | BK16: 0 | BL16: 0 | BM16: 0 | BN16: 0 | BO16: 0 | BP16: 0 | BQ16: 0 | BR16: 0 | BS16: 0 | BT16: 0 | BU16: 2483872.5 | BV16: 0
A17: 327 | B17: 0 | C17: 0 | D17: 0 | E17: 972697.97 | F17: 0 | G17: 0 | H17: 2049351.2 | I17: 18064.32 | J17: 3.2501754e+08 | K17: 1702.555 | L17: 157147.32 | M17: 6319.3632 | N17: 0 | O17: 285650.99 | P17: 14871.001 | Q17: 1362.9323 | R17: 125566.53 | S17: 1939.8767 | T17: 0 | U17: 12850.233 | V17: 34174.972 | W17: 41074.848 | X17: 0 | Y17: 7113921.7 | Z17: 340291.77 | AA17: 918244.92 | AB17: 2959229.1 | AC17: 0 | AD17: 0 | AE17: 0 | AF17: 0 | AG17: 0 | AH17: 0 | AI17: 0 | AJ17: 0 | AK17: 0 | AL17: 0 | AM17: 0 | AN17: 0 | AO17: 0 | AP17: 0 | AQ17: 0 | AR17: 0 | AS17: 0 | AT17: 0 | AU17: 0 | AV17: 0 | AW17: 0 | AX17: 0 | AY17: 0 | AZ17: 0 | BA17: 89287.086 | BB17: 1838888.8 | BC17: 0 | BD17: 0 | BE17: 0 | BF17: 0 | BG17: 0 | BH17: 0 | BI17: 0 | BJ17: 0 | BK17: 0 | BL17: 0 | BM17: 0 | BN17: 0 | BO17: 0 | BP17: 0 | BQ17: 0 | BR17: 0 | BS17: 0 | BT17: 0 | BU17: 8503.532 | BV17: 0
A18: 331 | B18: 0 | C18: 0 | D18: 0 | E18: 0 | F18: 0 | G18: 0 | H18: 163339.58 | I18: 0 | J18: 79191.785 | K18: 1.886179e+08 | L18: 2295017.4 | M18: 73715.933 | N18: 739.10681 | O18: 204782.6 | P18: 0 | Q18: 0 | R18: 0 | S18: 0 | T18: 0 | U18: 334.24485 | V18: 0 | W18: 586.80316 | X18: 0 | Y18: 32140958 | Z18: 370808.71 | AA18: 0 | AB18: 646718.5 | AC18: 0 | AD18: 0 | AE18: 0 | AF18: 0 | AG18: 0 | AH18: 0 | AI18: 0 | AJ18: 0 | AK18: 0 | AL18: 0 | AM18: 0 | AN18: 0 | AO18: 0 | AP18: 0 | AQ18: 0 | AR18: 0 | AS18: 0 | AT18: 0 | AU18: 0 | AV18: 0 | AW18: 0 | AX18: 0 | AY18: 0 | AZ18: 0 | BA18: 63742.275 | BB18: 312735.54 | BC18: 0 | BD18: 0 | BE18: 0 | BF18: 0 | BG18: 0 | BH18: 0 | BI18: 0 | BJ18: 0 | BK18: 0 | BL18: 0 | BM18: 0 | BN18: 0 | BO18: 0 | BP18: 0 | BQ18: 0 | BR18: 0 | BS18: 0 | BT18: 0 | BU18: 340622.78 | BV18: 0
A19: 332 | B19: 0 | C19: 0 | D19: 0 | E19: 0 | F19: 0 | G19: 0 | H19: 2019517.3 | I19: 86402.854 | J19: 173774.63 | K19: 2150922.6 | L19: 6.2637414e+08 | M19: 1009549.2 | N19: 410156.81 | O19: 177771.91 | P19: 208606.22 | Q19: 123946.13 | R19: 24654.282 | S19: 19291.614 | T19: 0 | U19: 20918.639 | V19: 0 | W19: 648.14027 | X19: 51782.496 | Y19: 82433.117 | Z19: 77944.004 | AA19: 1178598.9 | AB19: 2842706.7 | AC19: 0 | AD19: 0 | AE19: 0 | AF19: 0 | AG19: 0 | AH19: 0 | AI19: 0 | AJ19: 0 | AK19: 0 | AL19: 0 | AM19: 0 | AN19: 0 | AO19: 0 | AP19: 0 | AQ19: 0 | AR19: 0 | AS19: 0 | AT19: 0 | AU19: 0 | AV19: 0 | AW19: 0 | AX19: 0 | AY19: 0 | AZ19: 0 | BA19: 246728.36 | BB19: 2228170.3 | BC19: 0 | BD19: 0 | BE19: 0 | BF19: 0 | BG19: 0 | BH19: 0 | BI19: 0 | BJ19: 0 | BK19: 0 | BL19: 0 | BM19: 0 | BN19: 0 | BO19: 307648.95 | BP19: 0 | BQ19: 0 | BR19: 0 | BS19: 0 | BT19: 0 | BU19: 2595978.4 | BV19: 0
A20: 333 | B20: 0 | C20: 0 | D20: 0 | E20: 0 | F20: 7062.5474 | G20: 0 | H20: 4647156.2 | I20: 0 | J20: 294721.39 | K20: 89996.633 | L20: 24013923 | M20: 1.681331e+09 | N20: 3930290.8 | O20: 9121195.7 | P20: 2143475.2 | Q20: 3493185.1 | R20: 33908.098 | S20: 63690.929 | T20: 0 | U20: 0 | V20: 0 | W20: 0 | X20: 0 | Y20: 0 | Z20: 2096243.9 | AA20: 238477.68 | AB20: 35757677 | AC20: 0 | AD20: 0 | AE20: 0 | AF20: 0 | AG20: 0 | AH20: 0 | AI20: 0 | AJ20: 0 | AK20: 0 | AL20: 0 | AM20: 0 | AN20: 0 | AO20: 0 | AP20: 0 | AQ20: 0 | AR20: 0 | AS20: 0 | AT20: 0 | AU20: 0 | AV20: 0 | AW20: 0 | AX20: 0 | AY20: 91813.116 | AZ20: 0 | BA20: 4414092.1 | BB20: 64219743 | BC20: 0 | BD20: 0 | BE20: 0 | BF20: 0 | BG20: 0 | BH20: 0 | BI20: 0 | BJ20: 0 | BK20: 0 | BL20: 0 | BM20: 0 | BN20: 0 | BO20: 0 | BP20: 0 | BQ20: 0 | BR20: 0 | BS20: 0 | BT20: 0 | BU20: 2189389.7 | BV20: 0
... A79: GSLE | B79: 0 | C79: 0 | D79: 0 | E79: 0 | F79: 0 | G79: 2.3274998e+08 | H79: 0 | I79: 0 | J79: 0 | K79: 0 | L79: 0 | M79: 0 | N79: 0 | O79: 0 | P79: 0 | Q79: 0 | R79: 0 | S79: 0 | T79: 0 | U79: 0 | V79: 0 | W79: 0 | X79: 0 | Y79: 0 | Z79: 0 | AA79: 0 | AB79: 0 | AC79: 0 | AD79: 9099496.4 | AE79: 0 | AF79: 0 | AG79: 0 | AH79: 208168.72 | AI79: 725436.45 | AJ79: 0 | AK79: 27405728 | AL79: 0 | AM79: 25043328 | AN79: 0 | AO79: 0 | AP79: 0 | AQ79: 0 | AR79: 0 | AS79: 33117.751 | AT79: 0 | AU79: 687587.59 | AV79: 0 | AW79: 13453692 | AX79: 45625222 | AY79: 0 | AZ79: 0 | BA79: 0 | BB79: 0 | BC79: 0 | BD79: 0 | BE79: 0 | BF79: 0 | BG79: 0 | BH79: 0 | BI79: 0 | BJ79: 0 | BK79: 156126.54 | BL79: 68839188 | BM79: 0 | BN79: 0 | BO79: 5229450.6 | BP79: 0 | BQ79: 0 | BR79: 0 | BS79: 0 | BT79: 1.7380038e+08 | BU79: 0 | BV79: 0

Sheet Src_Disagg_EIA_coal
A1: Raw EIA Annual Coal Report (Form EIA-7A) 2019 state production values,
A2: used as the numerator for the 212 BEA mining disagg split (05 coal vs
A3: 07T08 other mining). Source:
A4: https://www.eia.gov/coal/annual/
A6: THIS STATE: SD
A9: state | B9: short_tons | C9: short_tons_units | D9: value_usd | E9: source_notes
A10: AL | B10: 12031000 | C10: short tons | D10: 600000000 | E10: EIA Annual Coal Report 2019; AL avg ~$50/ton bituminous
A11: AK | B11: 1000000 | C11: short tons | D11: 40000000 | E11: EIA Annual Coal Report 2019; AK Usibelli ~$40/ton subbit
A12: AZ | B12: 4220000 | C12: short tons | D12: 125000000 | E12: EIA Annual Coal Report 2019; Kayenta mine closed 2019; partial year
A13: AR | B13: 0 | C13: short tons | D13: 0
A14: CA | B14: 0 | C14: short tons | D14: 0
A15: CO | B15: 10710000 | C15: short tons | D15: 330000000 | E15: EIA ~$31/ton
A16: CT | B16: 0 | C16: short tons | D16: 0
A17: DE | B17: 0 | C17: short tons | D17: 0
A18: DC | B18: 0 | C18: short tons | D18: 0
A19: FL | B19: 0 | C19: short tons | D19: 0
A20: GA | B20: 0 | C20: short tons | D20: 0
A21: HI | B21: 0 | C21: short tons | D21: 0
A22: ID | B22: 0 | C22: short tons | D22: 0
A23: IL | B23: 45919000 | C23: short tons | D23: 1950000000 | E23: IL Basin avg ~$42/ton
A24: IN | B24: 28820000 | C24: short tons | D24: 1210000000 | E24: IL Basin avg ~$42/ton
A25: IA | B25: 0 | C25: short tons | D25: 0
A26: KS | B26: 0 | C26: short tons | D26: 0
A27: KY | B27: 36140000 | C27: short tons | D27: 1730000000 | E27: KY split East (Central App ~$58/ton) + West (IL Basin ~$40/ton)
A28: LA | B28: 2720000 | C28: short tons | D28: 60000000 | E28: lignite ~$22/ton
A29: ME | B29: 0 | C29: short tons | D29: 0
A30: MD | B30: 1320000 | C30: short tons | D30: 70000000 | E30: NA Appalachia ~$55/ton
A31: MA | B31: 0 | C31: short tons | D31: 0
A32: MI | B32: 0 | C32: short tons | D32: 0
A33: MN | B33: 0 | C33: short tons | D33: 0
A34: MS | B34: 2800000 | C34: short tons | D34: 65000000 | E34: lignite
A35: MO | B35: 264000 | C35: short tons | D35: 12000000
A36: MT | B36: 38660000 | C36: short tons | D36: 590000000 | E36: PRB subbit ~$14/ton + some bituminous
A37: NE | B37: 0 | C37: short tons | D37: 0
A38: NV | B38: 0 | C38: short tons | D38: 0
A39: NH | B39: 0 | C39: short tons | D39: 0
A40: NJ | B40: 0 | C40: short tons | D40: 0
A41: NM | B41: 10720000 | C41: short tons | D41: 260000000 | E41: San Juan + McKinley ~$24/ton
A42: NY | B42: 0 | C42: short tons | D42: 0
A43: NC | B43: 0 | C43: short tons | D43: 0
...

Sheet Src_Disagg_heuristics
A1: Hand-curated heuristic tables used as layer-3 fallback for BEA 327
A2: (nonmetallic) / 331 (primary metals) / 325 (chemicals) disaggregation
A3: when Census ASM is suppressed and GHGRP lacks coverage.
A5: Sources:
A6: - cement-heavy state list: GHGRP Subpart H 2019 facility presence
A7: + USGS Minerals Yearbook 2019 cement production rankings
A8: - glass-heavy state list: Census ASM 2017 NAICS 3272 top-6 states
A9: - steel_share: Census ASM 2017 NAICS 331 VA breakdown (2021 SUSB
A10: supplement where suppressed) + industry knowledge
A11: - pharma_share: Census ASM 2017 NAICS 325 VA breakdown +
A12: BLS QCEW 2019 NAICS 3254 employment share
A14: See R/build_state_overrides.R for the applied logic.
... A23: 331 / 325 heuristic split shares (used only where Census ASM / GHGRP unavailable):
A25: state | B25: 331_steel_share (-> ISIC 241) | C25: 331_other_share (-> ISIC 242) | D25: 325_pharma_share (-> ISIC 21) | E25: 325_chem_share (-> ISIC 20)
A26: AK | B26: 0.4 | C26: 0.6 | D26: 0.3 | E26: 0.7
A27: AL | B27: 0.7 | C27: 0.3 | D27: 0.15 | E27: 0.85
A28: AR | B28: 0.5 | C28: 0.5 | D28: 0.1 | E28: 0.9
A29: AZ | B29: 0.3 | C29: 0.7 | D29: 0.2 | E29: 0.8
A30: CA | B30: 0.35 | C30: 0.65 | D30: 0.55 | E30: 0.45
A31: CO | B31: 0.5 | C31: 0.5 | D31: 0.3 | E31: 0.7
A32: CT | B32: 0.4 | C32: 0.6 | D32: 0.5 | E32: 0.5
A33: DC | B33: 0.4 | C33: 0.6 | D33: 0.3 | E33: 0.7
A34: DE | B34: 0.5 | C34: 0.5 | D34: 0.4 | E34: 0.6
A35: FL | B35: 0.35 | C35: 0.65 | D35: 0.4 | E35: 0.6
A36: GA | B36: 0.5 | C36: 0.5 | D36: 0.3 | E36: 0.7
A37: HI | B37: 0.4 | C37: 0.6 | D37: 0.3 | E37: 0.7
... A76: WY | B76: 0.3 | C76: 0.7 | D76: 0.1 | E76: 0.9

Sheet Crosswalk_BEA_to_ISIC
A1: BEA Summary (post-disagg) -> 42-ISIC crosswalk, applied to state SD.
A3: Rows with allocation_weight != 1.0 represent BEA sectors that are split
A4: across multiple ISIC codes (e.g. BEA 22 utilities -> 351/352T353/36T39).
A5: State-specific overrides are loaded from crosswalks/state_overrides/<ST>/splits.csv.
A8: BEA_code | B8: BEA_name | C8: ISIC_code | D8: ISIC_name | E8: allocation_weight | F8: notes | G8: source
A9: 111CA | B9: Farms | C9: 01T03 | D9: Agriculture, forestry, fishing | E9: 1
A10: 113FF | B10: Forestry, fishing, related | C10: 01T03 | D10: Agriculture, forestry, fishing | E10: 1
A11: 211 | B11: Oil and gas extraction | C11: 06 | D11: Extraction of crude petroleum and natural gas | E11: 1
A12: 213 | B12: Support activities for mining | C12: 09 | D12: Mining support service activities | E12: 1
A13: 22 | B13: Utilities | C13: 351 | D13: Electricity | E13: 0.72 | F13: BEA 2012 Detail: electric ~72% of 22 output
A14: 22 | B14: Utilities | C14: 352T353 | D14: Gas, steam, AC | E14: 0.2 | F14: BEA Detail: gas distribution ~20%
A15: 22 | B15: Utilities | C15: 36T39 | D15: Water, sewerage, waste | E15: 0.08 | F15: BEA Detail: water/sewage ~8%
A16: 23 | B16: Construction | C16: 41T43 | D16: Construction | E16: 1
A17: 311FT | B17: Food, beverage, tobacco | C17: 10T12 | D17: Food, beverages, tobacco | E17: 1
A18: 313TT | B18: Textile mills and textile product mills | C18: 13T15 | D18: Textiles, apparel, leather | E18: 1
A19: 315AL | B19: Apparel and leather | C19: 13T15 | D19: Textiles, apparel, leather | E19: 1
A20: 321 | B20: Wood products | C20: 16 | D20: Wood and products of wood and cork | E20: 1
A21: 322 | B21: Paper products | C21: 17T18 | D21: Paper products and printing | E21: 1
A22: 323 | B22: Printing and related | C22: 17T18 | D22: Paper products and printing | E22: 1
A23: 324 | B23: Petroleum and coal products | C23: 19 | D23: Coke and refined petroleum products | E23: 0.961 | F23: BEA 2024 Detail: 324110 refineries + 324121/324122 asphalt = ~96.1% of 324 output ($601,241M / $625,936M)
A24: 324 | B24: Petroleum and coal products | C24: 241 | D24: Iron and steel (incl. coal coking) | E24: 0.039 | F24: EPS modeling convention: route NAICS 324190 (Other petroleum and coal products mfg, includes coal coking) to 241 to consolidate coke with iron and steel; matches eps-us national model
A25: 326 | B25: Plastics and rubber products | C25: 22 | D25: Rubber and plastics products | E25: 1
A26: 332 | B26: Fabricated metal products | C26: 25 | D26: Fabricated metal products | E26: 1
A27: 333 | B27: Machinery | C27: 28 | D27: Machinery and equipment n.e.c. | E27: 1
A28: 334 | B28: Computer and electronic products | C28: 26 | D28: Computer, electronic and optical products | E28: 1
A29: 335 | B29: Electrical equipment, appliances | C29: 27 | D29: Electrical equipment | E29: 1
A30: 3361MV | B30: Motor vehicles, bodies, trailers, parts | C30: 29 | D30: Motor vehicles, trailers, semi-trailers | E30: 1
A31: 3364OT | B31: Other transportation equipment | C31: 30 | D31: Other transport equipment | E31: 1
A32: 337 | B32: Furniture and related products | C32: 31T33 | D32: Furniture; other manufacturing; repair | E32: 1
A33: 339 | B33: Miscellaneous manufacturing | C33: 31T33 | D33: Furniture; other manufacturing; repair | E33: 1
A34: 42 | B34: Wholesale trade | C34: 45T47 | D34: Wholesale and retail trade | E34: 1
A35: 441 | B35: Motor vehicle and parts dealers | C35: 45T47 | D35: Wholesale and retail trade | E35: 1
A36: 445 | B36: Food and beverage stores | C36: 45T47 | D36: Wholesale and retail trade | E36: 1
... A43: 485 | B43: Transit and ground passenger | C43: 49T53 | D43: Transportation and storage | E43: 1
A44: 486 | B44: Pipeline transportation | C44: 352T353 | D44: Gas, steam, AC (incl. pipelines per EPS energy-side convention) | E44: 1 | F44: Reclassified from 49T53 (staff decision 2026-07-16): EPS 352T353 = 'energy pipelines and gas processing'; industrial-energy side sources pipeline fuel (AEO T36 / NAICS 486) here, so IO dollars follow. NOTE: diverges from eps-us national io-model (tags 486 -> 49T53); national files to be corrected separately.
A45: 487OS | B45: Other transportation and support | C45: 49T53 | D45: Transportation and storage | E45: 1
A46: 493 | B46: Warehousing and storage | C46: 49T53 | D46: Transportation and storage | E46: 1
A47: 511 | B47: Publishing industries (incl software) | C47: 58T60 | D47: Publishing, audiovisual, broadcasting | E47: 1
A48: 512 | B48: Motion picture and sound recording | C48: 58T60 | D48: Publishing, audiovisual, broadcasting | E48: 1
A49: 513 | B49: Broadcasting and telecom | C49: 58T60 | D49: Publishing, audiovisual, broadcasting | E49: 0.25 | F49: Placeholder ~25/75 broadcast/telecom per \u00a74.6
...

Sheet State_disagg_splits
A1: State-specific disaggregation ratios applied for SD.
A3: Five BEA Summary sectors are split into finer ISIC children. Ratios
A4: come from the layered proxy strategy in the migration plan (sec 4.0):
A5: 1. Pulled-from-source data (EIA-7A, Census ASM, GHGRP) where available
A6: 2. GHGRP emissions proxy where Census is suppressed
A7: 3. Hand-curated heuristic table (from industry knowledge)
A8: 4. National fallback ratio (last resort)
A11: BEA_code | B11: ISIC_code | C11: allocation_weight | D11: source
A12: 212 | B12: 05 | C12: 0 | D12: coal/(coal+nonfuel) mine-value share, 2012 USD: EIA coal 2019 $0M + USGS T3 nonfuel 2021 $405M -> coal share 0.000 (applied to stateior 212 $165M)
A13: 212 | B13: 07T08 | C13: 1 | D13: coal/(coal+nonfuel) mine-value share, 2012 USD: EIA coal 2019 $0M + USGS T3 nonfuel 2021 $405M -> coal share 0.000 (applied to stateior 212 $165M)
A14: 327 | B14: 231 | C14: 0.25 | D14: HEURISTIC (GHGRP Subpart H cement state list + glass industry profile; Census ASM suppressed or missing)
A15: 327 | B15: 239 | C15: 0.75 | D15: HEURISTIC (GHGRP Subpart H cement state list + glass industry profile; Census ASM suppressed or missing)
A16: 331 | B16: 241 | C16: 0.4 | D16: HEURISTIC (no ASM or GHGRP data pulled yet)
A17: 331 | B17: 242 | C17: 0.6 | D17: HEURISTIC (no ASM or GHGRP data pulled yet)
A18: 325 | B18: 20 | C18: 0.75 | D18: HEURISTIC (Census ASM suppressed or unpulled)
A19: 325 | B19: 21 | C19: 0.25 | D19: HEURISTIC (Census ASM suppressed or unpulled)

Sheet NAICS_to_ISIC_Key
A1: Concise NAICS Summary -> ISIC Rev 4 mapping used by this pipeline.
A2: See US Census Bureau NAICS 2017 to ISIC Rev 4 concordance for the full
A3: detail-level mapping:
A4: https://www.census.gov/naics/concordances/2017_NAICS_to_ISIC_4.xlsx
A7: ISIC Rev 4 code | B7: Title (42-ISIC scheme) | C7: BEA Summary sources (examples)
A8: 01T03 | B8: Agriculture, forestry and fishing | C8: 111CA Farms; 113FF Forestry/fishing/related
A9: 05 | B9: Mining of coal and lignite | C9: 212/coal (NAICS 2121)
A10: 06 | B10: Extraction of crude petroleum and natural gas | C10: 211 Oil and gas extraction
A11: 07T08 | B11: Mining of metal ores; other mining and quarrying | C11: 212/other (NAICS 2122+2123)
A12: 09 | B12: Mining support service activities | C12: 213 Support activities for mining
A13: 10T12 | B13: Food products, beverages and tobacco | C13: 311FT Food/beverage/tobacco
A14: 13T15 | B14: Textiles, wearing apparel, leather and related products | C14: 313TT Textile mills; 315AL Apparel/leather
A15: 16 | B15: Wood and products of wood and cork, except furniture | C15: 321 Wood products
A16: 17T18 | B16: Paper products and printing | C16: 322 Paper; 323 Printing
A17: 19 | B17: Coke and refined petroleum products | C17: 324 Petroleum and coal products
A18: 20 | B18: Chemicals and chemical products (excl. pharmaceuticals) | C18: 325/chem (NAICS 3251-3259 excl. 3254)
... A49: 97T98 | B49: Households as employers; undifferentiated production (zero in EPS) | C49: Designed zero row: households as employers (NAICS 814)

Sheet 5_Calc_ISIC_aggregation
A1: STEP 1 - read BEA code / ISIC code / weight live from the Crosswalk tab, pull each BEA value from the source tab, then weight it
A2: BEA_code | B2: ISIC_code | C2: allocation_weight | D2: BEA_value_nominal | E2: weighted_nominal
A3: ='Crosswalk_BEA_to_ISIC'!A9 | B3: ='Crosswalk_BEA_to_ISIC'!C9 | C3: ='Crosswalk_BEA_to_ISIC'!E9 | D3: =IFERROR(INDEX('1_Source_V001_Compensation'!$B$2:$B$72, MATCH($A3, '1_Source_V001_Compensation'!$A$2:$A$72, 0)), 0) | E3: =C3*D3
A4: ='Crosswalk_BEA_to_ISIC'!A10 | B4: ='Crosswalk_BEA_to_ISIC'!C10 | C4: ='Crosswalk_BEA_to_ISIC'!E10 | D4: =IFERROR(INDEX('1_Source_V001_Compensation'!$B$2:$B$72, MATCH($A4, '1_Source_V001_Compensation'!$A$2:$A$72, 0)), 0) | E4: =C4*D4
A5: ='Crosswalk_BEA_to_ISIC'!A11 | B5: ='Crosswalk_BEA_to_ISIC'!C11 | C5: ='Crosswalk_BEA_to_ISIC'!E11 | D5: =IFERROR(INDEX('1_Source_V001_Compensation'!$B$2:$B$72, MATCH($A5, '1_Source_V001_Compensation'!$A$2:$A$72, 0)), 0) | E5: =C5*D5
A6: ='Crosswalk_BEA_to_ISIC'!A12 | B6: ='Crosswalk_BEA_to_ISIC'!C12 | C6: ='Crosswalk_BEA_to_ISIC'!E12 | D6: =IFERROR(INDEX('1_Source_V001_Compensation'!$B$2:$B$72, MATCH($A6, '1_Source_V001_Compensation'!$A$2:$A$72, 0)), 0) | E6: =C6*D6
A7: ='Crosswalk_BEA_to_ISIC'!A13 | B7: ='Crosswalk_BEA_to_ISIC'!C13 | C7: ='Crosswalk_BEA_to_ISIC'!E13 | D7: =IFERROR(INDEX('1_Source_V001_Compensation'!$B$2:$B$72, MATCH($A7, '1_Source_V001_Compensation'!$A$2:$A$72, 0)), 0) | E7: =C7*D7
A8: ='Crosswalk_BEA_to_ISIC'!A14 | B8: ='Crosswalk_BEA_to_ISIC'!C14 | C8: ='Crosswalk_BEA_to_ISIC'!E14 | D8: =IFERROR(INDEX('1_Source_V001_Compensation'!$B$2:$B$72, MATCH($A8, '1_Source_V001_Compensation'!$A$2:$A$72, 0)), 0) | E8: =C8*D8
A9: ='Crosswalk_BEA_to_ISIC'!A15 | B9: ='Crosswalk_BEA_to_ISIC'!C15 | C9: ='Crosswalk_BEA_to_ISIC'!E15 | D9: =IFERROR(INDEX('1_Source_V001_Compensation'!$B$2:$B$72, MATCH($A9, '1_Source_V001_Compensation'!$A$2:$A$72, 0)), 0) | E9: =C9*D9
A10: ='Crosswalk_BEA_to_ISIC'!A16 | B10: ='Crosswalk_BEA_to_ISIC'!C16 | C10: ='Crosswalk_BEA_to_ISIC'!E16 | D10: =IFERROR(INDEX('1_Source_V001_Compensation'!$B$2:$B$72, MATCH($A10, '1_Source_V001_Compensation'!$A$2:$A$72, 0)), 0) | E10: =C10*D10
A11: ='Crosswalk_BEA_to_ISIC'!A17 | B11: ='Crosswalk_BEA_to_ISIC'!C17 | C11: ='Crosswalk_BEA_to_ISIC'!E17 | D11: =IFERROR(INDEX('1_Source_V001_Compensation'!$B$2:$B$72, MATCH($A11, '1_Source_V001_Compensation'!$A$2:$A$72, 0)), 0) | E11: =C11*D11
A12: ='Crosswalk_BEA_to_ISIC'!A18 | B12: ='Crosswalk_BEA_to_ISIC'!C18 | C12: ='Crosswalk_BEA_to_ISIC'!E18 | D12: =IFERROR(INDEX('1_Source_V001_Compensation'!$B$2:$B$72, MATCH($A12, '1_Source_V001_Compensation'!$A$2:$A$72, 0)), 0) | E12: =C12*D12
A13: ='Crosswalk_BEA_to_ISIC'!A19 | B13: ='Crosswalk_BEA_to_ISIC'!C19 | C13: ='Crosswalk_BEA_to_ISIC'!E19 | D13: =IFERROR(INDEX('1_Source_V001_Compensation'!$B$2:$B$72, MATCH($A13, '1_Source_V001_Compensation'!$A$2:$A$72, 0)), 0) | E13: =C13*D13
A14: ='Crosswalk_BEA_to_ISIC'!A20 | B14: ='Crosswalk_BEA_to_ISIC'!C20 | C14: ='Crosswalk_BEA_to_ISIC'!E20 | D14: =IFERROR(INDEX('1_Source_V001_Compensation'!$B$2:$B$72, MATCH($A14, '1_Source_V001_Compensation'!$A$2:$A$72, 0)), 0) | E14: =C14*D14
... A81: ='Crosswalk_BEA_to_ISIC'!A87 | B81: ='Crosswalk_BEA_to_ISIC'!C87 | C81: ='Crosswalk_BEA_to_ISIC'!E87 | D81: =IFERROR(INDEX('1_Source_V001_Compensation'!$B$2:$B$72, MATCH($A81, '1_Source_V001_Compensation'!$A$2:$A$72, 0)), 0) | E81: =C81*D81
A83: STEP 2 - aggregate weighted values to 42 ISIC, then deflate to 2012 USD (Keys!$C$2)
A84: ISIC_code | B84: aggregated_nominal | C84: value_2012USD
A85: 01T03 | B85: =SUMIFS('5_Calc_ISIC_aggregation'!$E$3:$E$81, '5_Calc_ISIC_aggregation'!$B$3:$B$81, $A85) | C85: =B85/Keys!$C$2
A86: 05 | B86: =SUMIFS('5_Calc_ISIC_aggregation'!$E$3:$E$81, '5_Calc_ISIC_aggregation'!$B$3:$B$81, $A86) | C86: =B86/Keys!$C$2
A87: 06 | B87: =SUMIFS('5_Calc_ISIC_aggregation'!$E$3:$E$81, '5_Calc_ISIC_aggregation'!$B$3:$B$81, $A87) | C87: =B87/Keys!$C$2
A88: 07T08 | B88: =SUMIFS('5_Calc_ISIC_aggregation'!$E$3:$E$81, '5_Calc_ISIC_aggregation'!$B$3:$B$81, $A88) | C88: =B88/Keys!$C$2
A89: 09 | B89: =SUMIFS('5_Calc_ISIC_aggregation'!$E$3:$E$81, '5_Calc_ISIC_aggregation'!$B$3:$B$81, $A89) | C89: =B89/Keys!$C$2
A90: 10T12 | B90: =SUMIFS('5_Calc_ISIC_aggregation'!$E$3:$E$81, '5_Calc_ISIC_aggregation'!$B$3:$B$81, $A90) | C90: =B90/Keys!$C$2
A91: 13T15 | B91: =SUMIFS('5_Calc_ISIC_aggregation'!$E$3:$E$81, '5_Calc_ISIC_aggregation'!$B$3:$B$81, $A91) | C91: =B91/Keys!$C$2
A92: 16 | B92: =SUMIFS('5_Calc_ISIC_aggregation'!$E$3:$E$81, '5_Calc_ISIC_aggregation'!$B$3:$B$81, $A92) | C92: =B92/Keys!$C$2
A93: 17T18 | B93: =SUMIFS('5_Calc_ISIC_aggregation'!$E$3:$E$81, '5_Calc_ISIC_aggregation'!$B$3:$B$81, $A93) | C93: =B93/Keys!$C$2
A94: 19 | B94: =SUMIFS('5_Calc_ISIC_aggregation'!$E$3:$E$81, '5_Calc_ISIC_aggregation'!$B$3:$B$81, $A94) | C94: =B94/Keys!$C$2
A95: 20 | B95: =SUMIFS('5_Calc_ISIC_aggregation'!$E$3:$E$81, '5_Calc_ISIC_aggregation'!$B$3:$B$81, $A95) | C95: =B95/Keys!$C$2
A96: 21 | B96: =SUMIFS('5_Calc_ISIC_aggregation'!$E$3:$E$81, '5_Calc_ISIC_aggregation'!$B$3:$B$81, $A96) | C96: =B96/Keys!$C$2
... A126: 97T98 | B126: =SUMIFS('5_Calc_ISIC_aggregation'!$E$3:$E$81, '5_Calc_ISIC_aggregation'!$B$3:$B$81, $A126) | C126: =B126/Keys!$C$2

Sheet BECbIC
A1: Unit: USD | B1: 01T03 | C1: 05 | D1: 06 | E1: 07T08 | F1: 09 | G1: 10T12 | H1: 13T15 | I1: 16 | J1: 17T18 | K1: 19 | L1: 20 | M1: 21 | N1: 22 | O1: 231 | P1: 239 | Q1: 241 | R1: 242 | S1: 25 | T1: 26 | U1: 27 | V1: 28 | W1: 29 | X1: 30 | Y1: 31T33 | Z1: 351 | AA1: 352T353 | AB1: 36T39 | AC1: 41T43 | AD1: 45T47 | AE1: 49T53 | AF1: 55T56 | AG1: 58T60 | AH1: 61 | AI1: 62T63 | AJ1: 64T66 | AK1: 68 | AL1: 69T82 | AM1: 84 | AN1: 85 | AO1: 86T88 | AP1: 90T96 | AQ1: 97T98
A2: Compensation | B2: =INDEX('5_Calc_ISIC_aggregation'!$C$85:$C$126, MATCH(B$1, '5_Calc_ISIC_aggregation'!$A$85:$A$126, 0)) | C2: =INDEX('5_Calc_ISIC_aggregation'!$C$85:$C$126, MATCH(C$1, '5_Calc_ISIC_aggregation'!$A$85:$A$126, 0)) | D2: =INDEX('5_Calc_ISIC_aggregation'!$C$85:$C$126, MATCH(D$1, '5_Calc_ISIC_aggregation'!$A$85:$A$126, 0)) | E2: =INDEX('5_Calc_ISIC_aggregation'!$C$85:$C$126, MATCH(E$1, '5_Calc_ISIC_aggregation'!$A$85:$A$126, 0)) | F2: =INDEX('5_Calc_ISIC_aggregation'!$C$85:$C$126, MATCH(F$1, '5_Calc_ISIC_aggregation'!$A$85:$A$126, 0)) | G2: =INDEX('5_Calc_ISIC_aggregation'!$C$85:$C$126, MATCH(G$1, '5_Calc_ISIC_aggregation'!$A$85:$A$126, 0)) | H2: =INDEX('5_Calc_ISIC_aggregation'!$C$85:$C$126, MATCH(H$1, '5_Calc_ISIC_aggregation'!$A$85:$A$126, 0)) | I2: =INDEX('5_Calc_ISIC_aggregation'!$C$85:$C$126, MATCH(I$1, '5_Calc_ISIC_aggregation'!$A$85:$A$126, 0)) | ... AQ2: =INDEX('5_Calc_ISIC_aggregation'!$C$85:$C$126, MATCH(AQ$1, '5_Calc_ISIC_aggregation'!$A$85:$A$126, 0))
